Workbook

Sheet Overview
A1: Game Outcome Simulator | Kanboard #2300 | Schema v0.1
A2: Owners Daniel + Adnan (Jashwant supporting). Prepared for the Oct 12 team meeting.
A4: Goal | B4: Replace the 1,200,000 coin lump sum with coins earned from game results. DM side defines the game outcome data first, a simulator fills it now, the MGI AI team's live data replaces it later. DM systems and LoopLab never care which source produced a row.
A5: Build choice | B5: Standalone Python script in MGI_Monorepo/Tools/GameOutcomeSimulator (outside Assets). Reads the same StreamingAssets JSON as the game. Outputs CSV for LoopLab and JSON for DM systems testing. Reference implementation gos_sim.py is attached and generated every sample in this workbook.
A7: What the professor asked (Coin Logic thread, Oct 2)
A8: Ask | B8: Where it is covered
A9: Define exactly what a completed game must output for DM consumption | B9: Schema_GameOutcome, Schema_SeasonSummary
A10: Win/Loss | B10: result
A11: Score | B11: points_for, points_against, margin
A12: Win count | B12: wins_to_date (per game), wins (per season)
A13: League/division | B13: league, division
A14: Streaks | B14: current_streak (per game), longest_win_streak (per season)
A15: Economy, Progression, Facilities, Coaches add to this list | B15: Consumer_Map shows each field and the code that consumes it
A16: Simulator data goes to LoopLab and DM systems testing | B16: CSV export (LoopLab) + JSON export (DM / StreamingAssets)
A17: Switch to live AI data later, DM systems should not care | B17: source field = simulator | live. Same schema, same validation
A18: Bhuvan: be careful simulating coin growth, fake income is the risk | B18: Coins come only from simulated results. Coin_Calibration is a placeholder for Economy/LoopLab to set
A20: Sheet guide
A21: Sheet | B21: What it is for
A22: Schema_GameOutcome | B22: THE CONTRACT. One row per team per game. Every field, type, rule, consumer
A23: Schema_SeasonSummary | B23: One row per team per season. Placement drives season rewards
A24: Schema_TeamInput | B24: What the simulator needs per team (ratings + coach bonuses)
A25: Team_Inputs | B25: Placeholder team values used in the samples. Strength is a live formula
A26: Consumer_Map | B26: Which subsystem reads which field, current values in the repo, status
A27: Sim_Config | B27: Every tunable parameter. Yellow cells are inputs
A28: Algorithm | B28: Step by step logic to replicate in code
A29: Win_Prob_Curve | B29: How strength gap turns into win chance. Reacts to Sim_Config
A30: Sample_Games / Sample_Standings | B30: One full simulated season (seed 42). Standings are formulas
A31: Validation | B31: Checks every batch must pass, sim or live. Live formulas on the sample
A32: Monte_Carlo | B32: 2,000 simulated seasons (seed 7). Targets to replicate against + charts
... A36: JSON_Example | B36: Exact JSON shape for one game (2 rows)
A38: Legend
A39: Yellow fill, blue text | B39: Input or assumption. Change it and formulas update
A40: Black text | B40: Formula or simulator output
A41: Green text | B41: Pulled from another sheet

Sheet Schema_GameOutcome
A1: Schema | game_outcomes (one row per team per game, 2 rows per game)
A2: Required = must be present for both simulator and live. 'Sim only' = null when source = live.
A4: # | B4: Field | C4: Type | D4: Required | E4: Example | F4: Rule / allowed values | G4: Description | H4: Prof list | I4: Consumed by | J4: Code reference
A5: 1 | B5: schema_version | C5: string | D5: Yes | E5: 0.1 | F5: semver, bump on any field change | G5: Version of this contract | I5: All
A6: 2 | B6: source | C6: enum | D6: Yes | E6: simulator | F6: simulator | live | G6: Who produced the row. The only thing that changes when we switch to the AI feed | I6: All | J6: Prof architecture (switch data streams)
A7: 3 | B7: run_id | C7: string | D7: Yes | E7: run-42 | G7: Batch id grouping one simulator run (live uses its own batch id) | I7: LoopLab
A8: 4 | B8: seed | C8: int | D8: Sim only | E8: 42 | F8: null for live | G8: RNG seed. Same seed + same config = identical output | I8: LoopLab
A9: 5 | B9: season_id | C9: string | D9: Yes | E9: S0001 | G9: Season identifier | I9: Progression | J9: SeasonSaveData.season_id
A10: 6 | B10: week | C10: int | D10: Yes | E10: 1 | F10: 1 .. weeks_per_season | G10: Week number | I10: Progression | J10: LocalSeasonBackend.current_week
A11: 7 | B11: game_id | C11: string | D11: Yes | E11: S0001-w01-g01 | F11: exactly 2 rows per game_id | G11: One id per game, shared by both teams' rows | I11: All
A12: 8 | B12: event_id | C12: string | D12: Yes | E12: S0001-w01-g01:<team_id> | F12: unique across all rows | G12: Idempotency key so a reward is never granted twice for the same game | I12: Economy, Progression, Coaches | J12: ProgressionService.AddXp(eventId). Today: "{season}:week:{n}:match"
A13: 9 | B13: game_type | C13: enum | D13: Yes | E13: regular | F13: regular | playoff | G13: Playoffs are future scope (BracketUI exists) | I13: Progression | J13: Progression/UI/BracketUI.cs
A14: 10 | B14: played_at | C14: ISO-8601 UTC | D14: Yes | E14: 2026-09-06T18:00:00Z | G14: When the game finished | I14: Economy ledger | J14: WalletTransaction.timestamp
A15: 11 | B15: team_id | C15: GUID | D15: Yes | E15: 22dda48d-... | F15: exists in team list for the season | G15: This row's team | I15: All | J15: team.json team_id. PR 92: id regenerates per season, use is_player_team for the user
A16: 12 | B16: team_name | C16: string | D16: Yes | E16: Buffalo Bills | G16: Display name | I16: UI, LoopLab | J16: team.json team_name
A17: 13 | B17: is_player_team | C17: bool | D17: Yes | E17: FALSE | F17: exactly 1 TRUE row per week | G17: Marks the user's team. Rewards only go to this team | I17: Economy, Progression, Coaches | J17: AwardSeasonRewards (PR 92)
A18: 14 | B18: player_id | C18: string | D18: If player team | E18: player_001 | F18: blank when is_player_team = FALSE | G18: Owner of wallet and progression | I18: Economy, Progression | J18: AddXp(playerId), EconomyService.AddCurrency(playerId, ...)
A19: 15 | B19: league | C19: string | D19: Yes | E19: NFL | F19: NFL | NFL-Historic | NCAA (team.json) | G19: League of the team | H19: Yes | I19: Economy / Facilities (future league caps) | J19: team.json league
A20: 16 | B20: division | C20: string | D20: Yes | E20: East | G20: Division inside the league | H20: Yes | I20: Standings, future league caps | J20: Not in repo yet
A21: 17 | B21: opponent_id | C21: GUID | D21: Yes | E21: 00000000-...-0001 | G21: Opponent team_id | I21: LoopLab
A22: 18 | B22: opponent_name | C22: string | D22: Yes | E22: Player Team | G22: Opponent display name | I22: UI, LoopLab
A23: 19 | B23: home_away | C23: enum | D23: Yes | E23: home | F23: home | away | G23: Venue | I23: LoopLab
A24: 20 | B24: result | C24: enum | D24: Yes | E24: W | F24: W | L (no ties in v0.1) | G24: Game result for this team | H24: Yes | I24: Progression XP, Coaches bonus, Economy coins | J24: AwardMatchXp, coaches_bonus_config.json xp_source = win
A25: 21 | B25: points_for | C25: int >= 0 | D25: Yes | E25: 32 | F25: W exactly when points_for > points_against | G25: Score for this team | H25: Yes | I25: Economy (optional margin bonus), LoopLab
A26: 22 | B26: points_against | C26: int >= 0 | D26: Yes | E26: 25 | G26: Score for opponent | H26: Yes | I26: LoopLab
A27: 23 | B27: margin | C27: int | D27: Yes | E27: 7 | F27: equals points_for - points_against | G27: Derived, included for convenience | H27: Yes | I27: LoopLab
A28: 24 | B28: wins_to_date | C28: int | D28: Yes | E28: 1 | F28: running count incl. this game | G28: Win count so far this season | H28: Yes | I28: Win count gates, Progression | J28: team.stats.wins
A29: 25 | B29: losses_to_date | C29: int | D29: Yes | E29: 0 | F29: running count incl. this game | G29: Loss count so far this season | I29: Progression | J29: team.stats.losses
A30: 26 | B30: current_streak | C30: int | D30: Yes | E30: 1 | F30: +N = N wins in a row, -N = N losses | G30: Streak after this game | H30: Yes | I30: Progression consecutive_win_bonus | J30: progression.json consecutive_win_bonus = 2 (not coded yet)
A31: 27 | B31: standing_points_to_date | C31: int | D31: Yes | E31: 2 | F31: equals wins_to_date x points_per_win | G31: League table points | I31: Progression standings | J31: team.stats.points = wins * 2
A32: 28 | B32: team_strength | C32: float | D32: Sim only | E32: 83.18 | F32: null for live | G32: Strength the simulator used for this team | I32: LoopLab analysis | J32: Team_Inputs
A33: 29 | B33: opponent_strength | C33: float | D33: Sim only | E33: 70.69 | F33: null for live | G33: Strength the simulator used for the opponent | I33: LoopLab analysis | J33: Team_Inputs
A34: 30 | B34: win_probability | C34: float 0..1 | D34: Sim only | E34: 0.7612 | F34: the 2 rows of a game sum to 1 | G34: Pre-game chance this team wins | I34: LoopLab analysis | J34: Win_Prob_Curve

Sheet Schema_SeasonSummary
A1: Schema | season_summary (one row per team per season)
A2: Produced after the last week. Placement drives season rewards.
A4: # | B4: Field | C4: Type | D4: Required | E4: Example | F4: Rule / allowed values | G4: Description | H4: Prof list | I4: Consumed by | J4: Code reference
A5: 1 | B5: schema_version | C5: string | D5: Yes | E5: 0.1 | G5: Contract version | I5: All
A6: 2 | B6: source | C6: enum | D6: Yes | E6: simulator | F6: simulator | live | G6: Producer | I6: All
A7: 3 | B7: run_id | C7: string | D7: Yes | E7: run-42 | G7: Batch id | I7: LoopLab
A8: 4 | B8: season_id | C8: string | D8: Yes | E8: S0001 | G8: Season | I8: Progression
A9: 5 | B9: team_id | C9: GUID | D9: Yes | G9: Team | I9: All
A10: 6 | B10: team_name | C10: string | D10: Yes | G10: Display name | I10: UI
A11: 7 | B11: is_player_team | C11: bool | D11: Yes | E11: TRUE | F11: exactly 1 per season | G11: User's team | I11: Economy, Progression | J11: AwardSeasonRewards
A12: 8 | B12: player_id | C12: string | D12: If player team | E12: player_001 | G12: Owner | I12: Economy, Progression
A13: 9 | B13: league | C13: string | D13: Yes | E13: NFL | G13: League | H13: Yes | I13: Future league caps
A14: 10 | B14: division | C14: string | D14: Yes | E14: West | G14: Division | H14: Yes | I14: Standings
A15: 11 | B15: games_played | C15: int | D15: Yes | E15: 10 | F15: equals weeks_per_season | G15: Games played | I15: Validation
A16: 12 | B16: wins | C16: int | D16: Yes | E16: 6 | F16: wins + losses = games_played | G16: Season win count | H16: Yes | I16: Win count gates
A17: 13 | B17: losses | C17: int | D17: Yes | E17: 4 | G17: Season losses
A18: 14 | B18: standing_points | C18: int | D18: Yes | E18: 12 | F18: equals wins x points_per_win | G18: Table points | I18: Progression | J18: team.stats.points
A19: 15 | B19: points_for | C19: int | D19: Yes | E19: 250 | G19: Total scored | H19: Yes | I19: Tiebreak, LoopLab
A20: 16 | B20: points_against | C20: int | D20: Yes | E20: 230 | G20: Total conceded | H20: Yes | I20: Tiebreak, LoopLab
A21: 17 | B21: point_diff | C21: int | D21: Yes | E21: 20 | F21: equals points_for - points_against | G21: Tiebreak 1 | I21: Tiebreak
A22: 18 | B22: longest_win_streak | C22: int | D22: Yes | E22: 3 | F22: >= 0 | G22: Best streak in season | H22: Yes | I22: Progression, LoopLab
A23: 19 | B23: placement | C23: int | D23: Yes | E23: 2 | F23: 1..N unique. Sort: points, then point_diff, then points_for, then team_id | G23: Final rank | I23: Progression season XP (50/30/15), proposed coin bonus | J23: LocalSeasonBackend.AwardSeasonRewards
A24: 20 | B24: team_strength | C24: float | D24: Sim only | E24: 70.69 | F24: null for live | G24: Sim strength | I24: LoopLab

Sheet Schema_TeamInput
A1: Schema | team_inputs (what the simulator reads per team)
A2: Today team.json has every rating = 1.0, so real values are an open question. Coach bonuses follow Jashwant's 3 rolled-up bonus proposal.
A4: # | B4: Field | C4: Type | D4: Range | E4: Source today | F4: Description
A5: 1 | B5: team_id | C5: GUID | E5: team.json team_id | F5: Team key
A6: 2 | B6: team_name | C6: string | E6: team.json team_name
A7: 3 | B7: league | C7: string | E7: team.json league
A8: 4 | B8: division | C8: string | E8: Not in repo. Assigned by simulator config
A9: 5 | B9: offence_rating | C9: float | D9: 0 - 100 | E9: team.json offence_rating (all 1.0 today) | F9: Offence strength
A10: 6 | B10: defence_rating | C10: float | D10: 0 - 100 | E10: team.json defence_rating (all 1.0 today) | F10: Defence strength
A11: 7 | B11: special_teams_rating | C11: float | D11: 0 - 100 | E11: team.json special_teams_rating (all 1.0 today) | F11: Special teams strength
A12: 8 | B12: coach_offence_bonus | C12: float | D12: 0 - 0.10 | E12: Coaches subsystem, rolled-up O bonus (Jashwant) | F12: Multiplier on offence: off x (1 + bonus)
A13: 9 | B13: coach_defence_bonus | C13: float | D13: 0 - 0.10 | E13: Coaches subsystem, rolled-up D bonus (Jashwant) | F13: Multiplier on defence
A14: 10 | B14: coach_special_teams_bonus | C14: float | D14: 0 - 0.10 | E14: Coaches subsystem, rolled-up ST bonus (Jashwant) | F14: Multiplier on special teams
A15: 11 | B15: is_player_team | C15: bool | E15: Season creation (CreateSeason playerTeamName) | F15: User's team

Sheet Sim_Config
A1: Sim_Config | every tunable parameter
A2: Yellow cells are inputs. Other sheets reference these cells by name.
A4: Parameter | B4: Value | C4: Unit | D4: Why this default
A5: weeks_per_season | B5: 10 | C5: weeks | D5: Matches LocalSeasonBackend total_weeks = 10
A6: points_per_win | B6: 2 | C6: points | D6: Matches team.stats.points = wins * 2
A7: teams_per_season | B7: 12 | C7: teams | D7: 11 NFL teams in team.json + the player's team. Must be even for round robin
A8: w_offence | B8: 0.45 | C8: weight | D8: Strength weights must sum to 1
A9: w_defence | B9: 0.4 | C9: weight
A10: w_special_teams | B10: 0.15 | C10: weight
A11: k | B11: 0.08 | C11: per strength pt | D11: 10 point strength gap -> about 69% win chance
A12: home_advantage | B12: 2 | C12: strength pts | D12: About +4% win chance for the home team
A13: loser_score_mean | B13: 20 | C13: points | D13: Football-like losing score
A14: loser_score_sd | B14: 6 | C14: points
A15: margin_base | B15: 3 | C15: points | D15: Typical margin between equal teams
A16: margin_per_strength | B16: 0.25 | C16: pts per strength pt | D16: Bigger gap -> bigger wins
A17: margin_sd | B17: 8 | C17: points
A18: sample_seed | B18: 42 | D18: Seed for Sample_Games
A19: monte_carlo_seed | B19: 7 | D19: Seed for Monte_Carlo
A20: monte_carlo_seasons | B20: 2000 | C20: seasons
A21: weight check (must be 1) | B21: =w_offence+w_defence+w_special_teams -> 1

Sheet Team_Inputs
A1: Team_Inputs | placeholder values used for every sample
A2: Names and team_ids are real (team.json, league NFL). Ratings and coach bonuses are invented tiers until Q1 is answered.
A4: team_id | B4: team_name | C4: league | D4: division | E4: offence_rating | F4: defence_rating | G4: special_teams_rating | H4: coach_offence_bonus | I4: coach_defence_bonus | J4: coach_special_teams_bonus | K4: is_player_team | L4: team_strength (formula)
A5: 22dda48d-9e4d-469d-8e17-eb48dd5a58d7 | B5: Buffalo Bills | C5: NFL | D5: East | E5: 84 | F5: 80 | G5: 72 | H5: 0.04 | I5: 0.03 | J5: 0.01 | K5: =FALSE() -> FALSE | L5: =w_offence*E5*(1+H5)+w_defence*F5*(1+I5)+w_special_teams*G5*(1+J5) -> 83.18
A6: 4379eea3-230b-4c63-8c33-06dacd51a349 | B6: New England Patriots | C6: NFL | D6: East | E6: 66 | F6: 70 | G6: 68 | H6: 0.02 | I6: 0.02 | J6: 0.01 | K6: =FALSE() -> FALSE | L6: =w_offence*E6*(1+H6)+w_defence*F6*(1+I6)+w_special_teams*G6*(1+J6) -> 69.156
A7: 88e80e3c-3511-403f-9033-332c76820e54 | B7: New York Giants | C7: NFL | D7: East | E7: 62 | F7: 64 | G7: 60 | H7: 0.01 | I7: 0.01 | J7: 0 | K7: =FALSE() -> FALSE | L7: =w_offence*E7*(1+H7)+w_defence*F7*(1+I7)+w_special_teams*G7*(1+J7) -> 63.035
A8: 3d743b76-bc76-4249-b550-d5a09b0e071a | B8: Dallas Cowboys | C8: NFL | D8: East | E8: 78 | F8: 72 | G8: 70 | H8: 0.03 | I8: 0.02 | J8: 0.01 | K8: =FALSE() -> FALSE | L8: =w_offence*E8*(1+H8)+w_defence*F8*(1+I8)+w_special_teams*G8*(1+J8) -> 76.134
A9: e6c4ce63-cbef-4e01-ba5f-804a984024ee | B9: Cincinnati Bengals | C9: NFL | D9: East | E9: 80 | F9: 66 | G9: 64 | H9: 0.03 | I9: 0.01 | J9: 0.01 | K9: =FALSE() -> FALSE | L9: =w_offence*E9*(1+H9)+w_defence*F9*(1+I9)+w_special_teams*G9*(1+J9) -> 73.44
A10: db3ed416-54bc-44d6-86dc-49b6cc79a2ef | B10: Cleveland Browns | C10: NFL | D10: East | E10: 58 | F10: 74 | G10: 62 | H10: 0.01 | I10: 0.03 | J10: 0 | K10: =FALSE() -> FALSE | L10: =w_offence*E10*(1+H10)+w_defence*F10*(1+I10)+w_special_teams*G10*(1+J10) -> 66.149
A11: 466adf39-b0a1-4b20-ba94-f22a82ff92a2 | B11: Los Angeles Rams | C11: NFL | D11: West | E11: 76 | F11: 74 | G11: 70 | H11: 0.03 | I11: 0.03 | J11: 0.01 | K11: =FALSE() -> FALSE | L11: =w_offence*E11*(1+H11)+w_defence*F11*(1+I11)+w_special_teams*G11*(1+J11) -> 76.319
A12: a866ce30-5869-4188-b93b-d415e1f97a9e | B12: Denver Broncos | C12: NFL | D12: West | E12: 64 | F12: 78 | G12: 66 | H12: 0.01 | I12: 0.04 | J12: 0.01 | K12: =FALSE() -> FALSE | L12: =w_offence*E12*(1+H12)+w_defence*F12*(1+I12)+w_special_teams*G12*(1+J12) -> 71.535
A13: 64336ace-1ead-4eed-a112-3d402edc6d84 | B13: New Orleans Saints | C13: NFL | D13: West | E13: 68 | F13: 64 | G13: 74 | H13: 0.02 | I13: 0.01 | J13: 0.02 | K13: =FALSE() -> FALSE | L13: =w_offence*E13*(1+H13)+w_defence*F13*(1+I13)+w_special_teams*G13*(1+J13) -> 68.39
A14: 7e907f08-6389-4d4f-b2b1-a4899a80a576 | B14: Chicago Bears | C14: NFL | D14: West | E14: 60 | F14: 70 | G14: 64 | H14: 0.01 | I14: 0.02 | J14: 0.01 | K14: =FALSE() -> FALSE | L14: =w_offence*E14*(1+H14)+w_defence*F14*(1+I14)+w_special_teams*G14*(1+J14) -> 65.526
A15: d6d0b322-6a53-4df9-9ae1-5abb357a05ef | B15: Carolina Panthers | C15: NFL | D15: West | E15: 56 | F15: 60 | G15: 58 | H15: 0 | I15: 0.01 | J15: 0 | K15: =FALSE() -> FALSE | L15: =w_offence*E15*(1+H15)+w_defence*F15*(1+I15)+w_special_teams*G15*(1+J15) -> 58.14
A16: 00000000-0000-0000-0000-000000000001 | B16: Player Team | C16: NFL | D16: West | E16: 70 | F16: 70 | G16: 66 | H16: 0.02 | I16: 0.02 | J16: 0.01 | K16: =TRUE() -> TRUE | L16: =w_offence*E16*(1+H16)+w_defence*F16*(1+I16)+w_special_teams*G16*(1+J16) -> 70.689

Sheet Consumer_Map
A1: Consumer_Map | who reads which field, and what the repo does today
A2: From MGI_Monorepo origin/main. Status: Wired = code exists, Config only = value exists but no code, Missing = nothing yet.
A4: Subsystem | B4: Field(s) | C4: What happens | D4: Current value in repo | E4: File / method | F4: Status
A5: Progression | B5: result | C5: Match XP for the player team: played + win or loss bonus | D5: 5 played, +10 win, +2 loss | E5: LocalSeasonBackend.AwardMatchXp, progression.json xp_reward_rules | F5: Wired
A6: Progression | B6: placement, is_player_team | C6: Season-end XP for top 3 | D6: 1st 50, 2nd 30, 3rd 15, else 0 | E6: LocalSeasonBackend.AwardSeasonRewards | F6: Wired
A7: Progression | B7: current_streak | C7: Consecutive win bonus | D7: 2 | E7: progression.json xp_calculation.consecutive_win_bonus | F7: Config only
A8: Progression | B8: standing_points_to_date, week | C8: Standings and season length | D8: points = wins x 2, 10 weeks | E8: LocalSeasonBackend.SimulateWeek / CreateSeason | F8: Wired
A9: Progression | B9: (today's source) | C9: Every match is a 50/50 coin flip, unseeded, ratings ignored, teams do not play each other so league wins != losses | D9: random.NextDouble() > 0.5 | E9: LocalSeasonBackend.SimulateWeek lines 173-205 | F9: Bug / replace
A10: Facilities | B10: via Progression XP | C10: Facility level multiplies Progression XP | D10: per facility level | E10: FacilitiesService.GetProgressionXpMultiplier | F10: Wired
A11: Facilities | B11: via Economy coins | C11: Coin sink: upgrade all 3 rooms to max | D11: Weight 477,000 + Film 296,000 + Rehab 385,000 = 1,158,000 | E11: facilities_config.json facility_definitions | F11: Wired
A12: Facilities | B12: via Progression tier | C12: Upgrade gates by tier | D12: rookie 2, pro 3, all_star 4, legend 5 | E12: facilities_config.json tier_upgrade_gates | F12: Wired
A13: Coaches | B13: result = W | C13: Coach XP bonus for O and D coaches, synergy when both hired, floored | D13: 0.03 + rating x 0.0004, synergy +0.02 | E13: coaches_bonus_config.json | F13: Wired
A14: Coaches | B14: (input to sim) | C14: Rolled-up O / D / ST bonuses feed team strength | D14: Proposed by Jashwant | E14: Coaches subsystem -> Team_Inputs | F14: Proposed
A15: Economy | B15: result, placement, event_id | C15: Coins per game / win / placement (replaces the lump sum) | D15: None. 1,200,000 lump sum | E15: EconomyService.AddCurrency(playerId, coins, gems, source) | F15: Missing
A16: Economy | B16: event_id, played_at | C16: Ledger idempotency and timestamp | D16: API exists, no caller | E16: WalletTransaction / GetRecentTransactions | F16: Wired API
A17: Economy / Facilities | B17: wins_to_date, league, division | C17: Win count gates, league caps (Sept 25 brainstorm list) | D17: None | F17: Future
A18: CCAS | B18: ? | C18: Pack rewards on results? | D18: Unknown | E18: StreamingAssets/CCAS/phase1_config.json, phase2_config.json | F18: Open (Q13)

Sheet Algorithm
A1: Algorithm | replicate this step by step
A2: Reference code: gos_sim.py (function names in column D).
A4: Step | B4: What | C4: Exact logic | D4: Function in gos_sim.py
A5: 1 | B5: Load inputs | C5: Read Sim_Config + team inputs. v0.1: hardcoded tables. v0.2: load team.json, progression.json, coaches_bonus_config.json, facilities_config.json from StreamingAssets | D5: CONFIG, TEAMS
A6: 2 | B6: Team strength | C6: S = w_offence x off x (1 + coach_o) + w_defence x def x (1 + coach_d) + w_special_teams x st x (1 + coach_st) | D6: team_strength()
A7: 3 | B7: Schedule | C7: Circle round robin. N teams (even). Fix team 0, rotate the rest. Take the first weeks_per_season rounds. Pair i: (idx[i], idx[N-1-i]), flip home/away when (round + i) is odd | D7: round_robin()
A8: 4 | B8: Win chance | C8: p_home = 1 / (1 + exp(-k x (S_home - S_away + home_advantage))) | D8: win_probability()
A9: 5 | B9: Decide winner | C9: u = rng.random(). Home wins if u < p_home. ONE rng seeded once per run, never reseeded per game | D9: simulate_season()
A10: 6 | B10: Score | C10: loser = max(0, round(N(loser_score_mean, loser_score_sd))). margin = max(1, round(|N(margin_base + margin_per_strength x |S_home - S_away|, margin_sd)|)). winner = loser + margin. No ties | D10: simulate_season()
A11: 7 | B11: Emit rows | C11: 2 rows per game (home first, then away). Update running wins, losses, points_for, points_against, streak (+1 or reset to +1 on win, -1 or reset to -1 on loss), standing points | D11: simulate_season()
A12: 8 | B12: Standings | C12: After the last week sort by standing_points desc, point_diff desc, points_for desc, team_id asc. Placement = position (1..N) | D12: simulate_season()
A13: 9 | B13: Many seasons | C13: Repeat steps 3-8 for --seasons N with the same rng. season_id = S0001, S0002 ... | D13: run()
A14: 10 | B14: Validate | C14: Run every check on the Validation sheet. Refuse to export if any fails | D14: validate()
A15: 11 | B15: Export | C15: game_outcomes.csv + season_summary.csv for LoopLab. game_outcomes.json {schema_version, games, seasons} for DM systems | D15: write()
A16: 12 | B16: Replication target | C16: Exact rows will differ across languages (different RNGs). Instead: run 2,000 seasons with default config, each team's average wins must be within +/- 0.15 of the Monte_Carlo sheet

Sheet Win_Prob_Curve
A1: Win_Prob_Curve | strength gap -> win chance
A2: Formulas read k and home_advantage from Sim_Config. Change them there and the chart moves.
A4: Strength gap (team - opponent) | B4: P(win) at home | C4: P(win) neutral | D4: P(win) away
A5: -30 | B5: =1/(1+EXP(-k*(A5+home_advantage))) -> 0.096215542 | C5: =1/(1+EXP(-k*A5)) -> 0.083172696 | D5: =1/(1+EXP(-k*(A5-home_advantage))) -> 0.071757542
A6: -28 | B6: =1/(1+EXP(-k*(A6+home_advantage))) -> 0.11105597 | C6: =1/(1+EXP(-k*A6)) -> 0.096215542 | D6: =1/(1+EXP(-k*(A6-home_advantage))) -> 0.083172696
A7: -26 | B7: =1/(1+EXP(-k*(A7+home_advantage))) -> 0.12786157 | C7: =1/(1+EXP(-k*A7)) -> 0.11105597 | D7: =1/(1+EXP(-k*(A7-home_advantage))) -> 0.096215542
A8: -24 | B8: =1/(1+EXP(-k*(A8+home_advantage))) -> 0.14679034 | C8: =1/(1+EXP(-k*A8)) -> 0.12786157 | D8: =1/(1+EXP(-k*(A8-home_advantage))) -> 0.11105597
A9: -22 | B9: =1/(1+EXP(-k*(A9+home_advantage))) -> 0.16798161 | C9: =1/(1+EXP(-k*A9)) -> 0.14679034 | D9: =1/(1+EXP(-k*(A9-home_advantage))) -> 0.12786157
A10: -20 | B10: =1/(1+EXP(-k*(A10+home_advantage))) -> 0.19154535 | C10: =1/(1+EXP(-k*A10)) -> 0.16798161 | D10: =1/(1+EXP(-k*(A10-home_advantage))) -> 0.14679034
A11: -18 | B11: =1/(1+EXP(-k*(A11+home_advantage))) -> 0.21755022 | C11: =1/(1+EXP(-k*A11)) -> 0.19154535 | D11: =1/(1+EXP(-k*(A11-home_advantage))) -> 0.16798161
A12: -16 | B12: =1/(1+EXP(-k*(A12+home_advantage))) -> 0.24601128 | C12: =1/(1+EXP(-k*A12)) -> 0.21755022 | D12: =1/(1+EXP(-k*(A12-home_advantage))) -> 0.19154535
A13: -14 | B13: =1/(1+EXP(-k*(A13+home_advantage))) -> 0.27687819 | C13: =1/(1+EXP(-k*A13)) -> 0.24601128 | D13: =1/(1+EXP(-k*(A13-home_advantage))) -> 0.21755022
A14: -12 | B14: =1/(1+EXP(-k*(A14+home_advantage))) -> 0.31002552 | C14: =1/(1+EXP(-k*A14)) -> 0.27687819 | D14: =1/(1+EXP(-k*(A14-home_advantage))) -> 0.24601128
A15: -10 | B15: =1/(1+EXP(-k*(A15+home_advantage))) -> 0.34524654 | C15: =1/(1+EXP(-k*A15)) -> 0.31002552 | D15: =1/(1+EXP(-k*(A15-home_advantage))) -> 0.27687819
A16: -8 | B16: =1/(1+EXP(-k*(A16+home_advantage))) -> 0.38225213 | C16: =1/(1+EXP(-k*A16)) -> 0.34524654 | D16: =1/(1+EXP(-k*(A16-home_advantage))) -> 0.31002552
... A35: 30 | B35: =1/(1+EXP(-k*(A35+home_advantage))) -> 0.92824246 | C35: =1/(1+EXP(-k*A35)) -> 0.9168273 | D35: =1/(1+EXP(-k*(A35-home_advantage))) -> 0.90378446

Sheet Sample_Games
A1: schema_version | B1: source | C1: run_id | D1: seed | E1: season_id | F1: week | G1: game_id | H1: event_id | I1: game_type | J1: played_at | K1: team_id | L1: team_name | M1: is_player_team | N1: player_id | O1: league | P1: division | Q1: opponent_id | R1: opponent_name | S1: home_away | T1: result | U1: points_for | V1: points_against | W1: margin | X1: wins_to_date | Y1: losses_to_date | Z1: current_streak | AA1: standing_points_to_date | AB1: team_strength | AC1: opponent_strength | AD1: win_probability
A2: 0.1 | B2: simulator | C2: run-42 | D2: 42 | E2: S0001 | F2: 1 | G2: S0001-w01-g01 | H2: S0001-w01-g01:22dda48d-9e4d-469d-8e17-eb48dd5a58d7 | I2: regular | J2: 2026-09-06T18:00:00+00:00 | K2: 22dda48d-9e4d-469d-8e17-eb48dd5a58d7 | L2: Buffalo Bills | M2: =FALSE() -> FALSE | O2: NFL | P2: East | Q2: 00000000-0000-0000-0000-000000000001 | R2: Player Team | S2: home | T2: W | U2: 32 | V2: 25 | W2: 7 | X2: 1 | Y2: 0 | Z2: 1 | AA2: 2 | AB2: 83.18 | AC2: 70.69 | AD2: 0.7612
A3: 0.1 | B3: simulator | C3: run-42 | D3: 42 | E3: S0001 | F3: 1 | G3: S0001-w01-g01 | H3: S0001-w01-g01:00000000-0000-0000-0000-000000000001 | I3: regular | J3: 2026-09-06T18:00:00+00:00 | K3: 00000000-0000-0000-0000-000000000001 | L3: Player Team | M3: =TRUE() -> TRUE | N3: player_001 | O3: NFL | P3: West | Q3: 22dda48d-9e4d-469d-8e17-eb48dd5a58d7 | R3: Buffalo Bills | S3: away | T3: L | U3: 25 | V3: 32 | W3: -7 | X3: 0 | Y3: 1 | Z3: -1 | AA3: 0 | AB3: 70.69 | AC3: 83.18 | AD3: 0.2388
A4: 0.1 | B4: simulator | C4: run-42 | D4: 42 | E4: S0001 | F4: 1 | G4: S0001-w01-g02 | H4: S0001-w01-g02:d6d0b322-6a53-4df9-9ae1-5abb357a05ef | I4: regular | J4: 2026-09-06T18:00:00+00:00 | K4: d6d0b322-6a53-4df9-9ae1-5abb357a05ef | L4: Carolina Panthers | M4: =FALSE() -> FALSE | O4: NFL | P4: West | Q4: 4379eea3-230b-4c63-8c33-06dacd51a349 | R4: New England Patriots | S4: home | T4: W | U4: 25 | V4: 19 | W4: 6 | X4: 1 | Y4: 0 | Z4: 1 | AA4: 2 | AB4: 58.14 | AC4: 69.16 | AD4: 0.3271
A5: 0.1 | B5: simulator | C5: run-42 | D5: 42 | E5: S0001 | F5: 1 | G5: S0001-w01-g02 | H5: S0001-w01-g02:4379eea3-230b-4c63-8c33-06dacd51a349 | I5: regular | J5: 2026-09-06T18:00:00+00:00 | K5: 4379eea3-230b-4c63-8c33-06dacd51a349 | L5: New England Patriots | M5: =FALSE() -> FALSE | O5: NFL | P5: East | Q5: d6d0b322-6a53-4df9-9ae1-5abb357a05ef | R5: Carolina Panthers | S5: away | T5: L | U5: 19 | V5: 25 | W5: -6 | X5: 0 | Y5: 1 | Z5: -1 | AA5: 0 | AB5: 69.16 | AC5: 58.14 | AD5: 0.6729
A6: 0.1 | B6: simulator | C6: run-42 | D6: 42 | E6: S0001 | F6: 1 | G6: S0001-w01-g03 | H6: S0001-w01-g03:88e80e3c-3511-403f-9033-332c76820e54 | I6: regular | J6: 2026-09-06T18:00:00+00:00 | K6: 88e80e3c-3511-403f-9033-332c76820e54 | L6: New York Giants | M6: =FALSE() -> FALSE | O6: NFL | P6: East | Q6: 7e907f08-6389-4d4f-b2b1-a4899a80a576 | R6: Chicago Bears | S6: home | T6: L | U6: 25 | V6: 33 | W6: -8 | X6: 0 | Y6: 1 | Z6: -1 | AA6: 0 | AB6: 63.04 | AC6: 65.53 | AD6: 0.4902
A7: 0.1 | B7: simulator | C7: run-42 | D7: 42 | E7: S0001 | F7: 1 | G7: S0001-w01-g03 | H7: S0001-w01-g03:7e907f08-6389-4d4f-b2b1-a4899a80a576 | I7: regular | J7: 2026-09-06T18:00:00+00:00 | K7: 7e907f08-6389-4d4f-b2b1-a4899a80a576 | L7: Chicago Bears | M7: =FALSE() -> FALSE | O7: NFL | P7: West | Q7: 88e80e3c-3511-403f-9033-332c76820e54 | R7: New York Giants | S7: away | T7: W | U7: 33 | V7: 25 | W7: 8 | X7: 1 | Y7: 0 | Z7: 1 | AA7: 2 | AB7: 65.53 | AC7: 63.04 | AD7: 0.5098
A8: 0.1 | B8: simulator | C8: run-42 | D8: 42 | E8: S0001 | F8: 1 | G8: S0001-w01-g04 | H8: S0001-w01-g04:64336ace-1ead-4eed-a112-3d402edc6d84 | I8: regular | J8: 2026-09-06T18:00:00+00:00 | K8: 64336ace-1ead-4eed-a112-3d402edc6d84 | L8: New Orleans Saints | M8: =FALSE() -> FALSE | O8: NFL | P8: West | Q8: 3d743b76-bc76-4249-b550-d5a09b0e071a | R8: Dallas Cowboys | S8: home | T8: W | U8: 35 | V8: 21 | W8: 14 | X8: 1 | Y8: 0 | Z8: 1 | AA8: 2 | AB8: 68.39 | AC8: 76.13 | AD8: 0.3871
A9: 0.1 | B9: simulator | C9: run-42 | D9: 42 | E9: S0001 | F9: 1 | G9: S0001-w01-g04 | H9: S0001-w01-g04:3d743b76-bc76-4249-b550-d5a09b0e071a | I9: regular | J9: 2026-09-06T18:00:00+00:00 | K9: 3d743b76-bc76-4249-b550-d5a09b0e071a | L9: Dallas Cowboys | M9: =FALSE() -> FALSE | O9: NFL | P9: East | Q9: 64336ace-1ead-4eed-a112-3d402edc6d84 | R9: New Orleans Saints | S9: away | T9: L | U9: 21 | V9: 35 | W9: -14 | X9: 0 | Y9: 1 | Z9: -1 | AA9: 0 | AB9: 76.13 | AC9: 68.39 | AD9: 0.6129
A10: 0.1 | B10: simulator | C10: run-42 | D10: 42 | E10: S0001 | F10: 1 | G10: S0001-w01-g05 | H10: S0001-w01-g05:e6c4ce63-cbef-4e01-ba5f-804a984024ee | I10: regular | J10: 2026-09-06T18:00:00+00:00 | K10: e6c4ce63-cbef-4e01-ba5f-804a984024ee | L10: Cincinnati Bengals | M10: =FALSE() -> FALSE | O10: NFL | P10: East | Q10: a866ce30-5869-4188-b93b-d415e1f97a9e | R10: Denver Broncos | S10: home | T10: W | U10: 37 | V10: 23 | W10: 14 | X10: 1 | Y10: 0 | Z10: 1 | AA10: 2 | AB10: 73.44 | AC10: 71.54 | AD10: 0.5775
A11: 0.1 | B11: simulator | C11: run-42 | D11: 42 | E11: S0001 | F11: 1 | G11: S0001-w01-g05 | H11: S0001-w01-g05:a866ce30-5869-4188-b93b-d415e1f97a9e | I11: regular | J11: 2026-09-06T18:00:00+00:00 | K11: a866ce30-5869-4188-b93b-d415e1f97a9e | L11: Denver Broncos | M11: =FALSE() -> FALSE | O11: NFL | P11: West | Q11: e6c4ce63-cbef-4e01-ba5f-804a984024ee | R11: Cincinnati Bengals | S11: away | T11: L | U11: 23 | V11: 37 | W11: -14 | X11: 0 | Y11: 1 | Z11: -1 | AA11: 0 | AB11: 71.54 | AC11: 73.44 | AD11: 0.4225
A12: 0.1 | B12: simulator | C12: run-42 | D12: 42 | E12: S0001 | F12: 1 | G12: S0001-w01-g06 | H12: S0001-w01-g06:466adf39-b0a1-4b20-ba94-f22a82ff92a2 | I12: regular | J12: 2026-09-06T18:00:00+00:00 | K12: 466adf39-b0a1-4b20-ba94-f22a82ff92a2 | L12: Los Angeles Rams | M12: =FALSE() -> FALSE | O12: NFL | P12: West | Q12: db3ed416-54bc-44d6-86dc-49b6cc79a2ef | R12: Cleveland Browns | S12: home | T12: W | U12: 37 | V12: 21 | W12: 16 | X12: 1 | Y12: 0 | Z12: 1 | AA12: 2 | AB12: 76.32 | AC12: 66.15 | AD12: 0.7258
A13: 0.1 | B13: simulator | C13: run-42 | D13: 42 | E13: S0001 | F13: 1 | G13: S0001-w01-g06 | H13: S0001-w01-g06:db3ed416-54bc-44d6-86dc-49b6cc79a2ef | I13: regular | J13: 2026-09-06T18:00:00+00:00 | K13: db3ed416-54bc-44d6-86dc-49b6cc79a2ef | L13: Cleveland Browns | M13: =FALSE() -> FALSE | O13: NFL | P13: East | Q13: 466adf39-b0a1-4b20-ba94-f22a82ff92a2 | R13: Los Angeles Rams | S13: away | T13: L | U13: 21 | V13: 37 | W13: -16 | X13: 0 | Y13: 1 | Z13: -1 | AA13: 0 | AB13: 66.15 | AC13: 76.32 | AD13: 0.2742
A14: 0.1 | B14: simulator | C14: run-42 | D14: 42 | E14: S0001 | F14: 2 | G14: S0001-w02-g01 | H14: S0001-w02-g01:d6d0b322-6a53-4df9-9ae1-5abb357a05ef | I14: regular | J14: 2026-09-13T18:00:00+00:00 | K14: d6d0b322-6a53-4df9-9ae1-5abb357a05ef | L14: Carolina Panthers | M14: =FALSE() -> FALSE | O14: NFL | P14: West | Q14: 22dda48d-9e4d-469d-8e17-eb48dd5a58d7 | R14: Buffalo Bills | S14: home | T14: L | U14: 31 | V14: 41 | W14: -10 | X14: 1 | Y14: 1 | Z14: -1 | AA14: 2 | AB14: 58.14 | AC14: 83.18 | AD14: 0.1367
A15: 0.1 | B15: simulator | C15: run-42 | D15: 42 | E15: S0001 | F15: 2 | G15: S0001-w02-g01 | H15: S0001-w02-g01:22dda48d-9e4d-469d-8e17-eb48dd5a58d7 | I15: regular | J15: 2026-09-13T18:00:00+00:00 | K15: 22dda48d-9e4d-469d-8e17-eb48dd5a58d7 | L15: Buffalo Bills | M15: =FALSE() -> FALSE | O15: NFL | P15: East | Q15: d6d0b322-6a53-4df9-9ae1-5abb357a05ef | R15: Carolina Panthers | S15: away | T15: W | U15: 41 | V15: 31 | W15: 10 | X15: 2 | Y15: 0 | Z15: 2 | AA15: 4 | AB15: 83.18 | AC15: 58.14 | AD15: 0.8633
A16: 0.1 | B16: simulator | C16: run-42 | D16: 42 | E16: S0001 | F16: 2 | G16: S0001-w02-g02 | H16: S0001-w02-g02:00000000-0000-0000-0000-000000000001 | I16: regular | J16: 2026-09-13T18:00:00+00:00 | K16: 00000000-0000-0000-0000-000000000001 | L16: Player Team | M16: =TRUE() -> TRUE | N16: player_001 | O16: NFL | P16: West | Q16: 7e907f08-6389-4d4f-b2b1-a4899a80a576 | R16: Chicago Bears | S16: home | T16: L | U16: 18 | V16: 26 | W16: -8 | X16: 0 | Y16: 2 | Z16: -2 | AA16: 0 | AB16: 70.69 | AC16: 65.53 | AD16: 0.6395
A17: 0.1 | B17: simulator | C17: run-42 | D17: 42 | E17: S0001 | F17: 2 | G17: S0001-w02-g02 | H17: S0001-w02-g02:7e907f08-6389-4d4f-b2b1-a4899a80a576 | I17: regular | J17: 2026-09-13T18:00:00+00:00 | K17: 7e907f08-6389-4d4f-b2b1-a4899a80a576 | L17: Chicago Bears | M17: =FALSE() -> FALSE | O17: NFL | P17: West | Q17: 00000000-0000-0000-0000-000000000001 | R17: Player Team | S17: away | T17: W | U17: 26 | V17: 18 | W17: 8 | X17: 2 | Y17: 0 | Z17: 2 | AA17: 4 | AB17: 65.53 | AC17: 70.69 | AD17: 0.3605
A18: 0.1 | B18: simulator | C18: run-42 | D18: 42 | E18: S0001 | F18: 2 | G18: S0001-w02-g03 | H18: S0001-w02-g03:64336ace-1ead-4eed-a112-3d402edc6d84 | I18: regular | J18: 2026-09-13T18:00:00+00:00 | K18: 64336ace-1ead-4eed-a112-3d402edc6d84 | L18: New Orleans Saints | M18: =FALSE() -> FALSE | O18: NFL | P18: West | Q18: 4379eea3-230b-4c63-8c33-06dacd51a349 | R18: New England Patriots | S18: home | T18: L | U18: 19 | V18: 25 | W18: -6 | X18: 1 | Y18: 1 | Z18: -1 | AA18: 2 | AB18: 68.39 | AC18: 69.16 | AD18: 0.5247
A19: 0.1 | B19: simulator | C19: run-42 | D19: 42 | E19: S0001 | F19: 2 | G19: S0001-w02-g03 | H19: S0001-w02-g03:4379eea3-230b-4c63-8c33-06dacd51a349 | I19: regular | J19: 2026-09-13T18:00:00+00:00 | K19: 4379eea3-230b-4c63-8c33-06dacd51a349 | L19: New England Patriots | M19: =FALSE() -> FALSE | O19: NFL | P19: East | Q19: 64336ace-1ead-4eed-a112-3d402edc6d84 | R19: New Orleans Saints | S19: away | T19: W | U19: 25 | V19: 19 | W19: 6 | X19: 1 | Y19: 1 | Z19: 1 | AA19: 2 | AB19: 69.16 | AC19: 68.39 | AD19: 0.4753
A20: 0.1 | B20: simulator | C20: run-42 | D20: 42 | E20: S0001 | F20: 2 | G20: S0001-w02-g04 | H20: S0001-w02-g04:88e80e3c-3511-403f-9033-332c76820e54 | I20: regular | J20: 2026-09-13T18:00:00+00:00 | K20: 88e80e3c-3511-403f-9033-332c76820e54 | L20: New York Giants | M20: =FALSE() -> FALSE | O20: NFL | P20: East | Q20: a866ce30-5869-4188-b93b-d415e1f97a9e | R20: Denver Broncos | S20: home | T20: W | U20: 29 | V20: 25 | W20: 4 | X20: 1 | Y20: 1 | Z20: 1 | AA20: 2 | AB20: 63.04 | AC20: 71.54 | AD20: 0.3729
A21: 0.1 | B21: simulator | C21: run-42 | D21: 42 | E21: S0001 | F21: 2 | G21: S0001-w02-g04 | H21: S0001-w02-g04:a866ce30-5869-4188-b93b-d415e1f97a9e | I21: regular | J21: 2026-09-13T18:00:00+00:00 | K21: a866ce30-5869-4188-b93b-d415e1f97a9e | L21: Denver Broncos | M21: =FALSE() -> FALSE | O21: NFL | P21: West | Q21: 88e80e3c-3511-403f-9033-332c76820e54 | R21: New York Giants | S21: away | T21: L | U21: 25 | V21: 29 | W21: -4 | X21: 0 | Y21: 2 | Z21: -2 | AA21: 0 | AB21: 71.54 | AC21: 63.04 | AD21: 0.6271
A22: 0.1 | B22: simulator | C22: run-42 | D22: 42 | E22: S0001 | F22: 2 | G22: S0001-w02-g05 | H22: S0001-w02-g05:466adf39-b0a1-4b20-ba94-f22a82ff92a2 | I22: regular | J22: 2026-09-13T18:00:00+00:00 | K22: 466adf39-b0a1-4b20-ba94-f22a82ff92a2 | L22: Los Angeles Rams | M22: =FALSE() -> FALSE | O22: NFL | P22: West | Q22: 3d743b76-bc76-4249-b550-d5a09b0e071a | R22: Dallas Cowboys | S22: home | T22: L | U22: 19 | V22: 26 | W22: -7 | X22: 1 | Y22: 1 | Z22: -1 | AA22: 2 | AB22: 76.32 | AC22: 76.13 | AD22: 0.5436
A23: 0.1 | B23: simulator | C23: run-42 | D23: 42 | E23: S0001 | F23: 2 | G23: S0001-w02-g05 | H23: S0001-w02-g05:3d743b76-bc76-4249-b550-d5a09b0e071a | I23: regular | J23: 2026-09-13T18:00:00+00:00 | K23: 3d743b76-bc76-4249-b550-d5a09b0e071a | L23: Dallas Cowboys | M23: =FALSE() -> FALSE | O23: NFL | P23: East | Q23: 466adf39-b0a1-4b20-ba94-f22a82ff92a2 | R23: Los Angeles Rams | S23: away | T23: W | U23: 26 | V23: 19 | W23: 7 | X23: 1 | Y23: 1 | Z23: 1 | AA23: 2 | AB23: 76.13 | AC23: 76.32 | AD23: 0.4564
A24: 0.1 | B24: simulator | C24: run-42 | D24: 42 | E24: S0001 | F24: 2 | G24: S0001-w02-g06 | H24: S0001-w02-g06:e6c4ce63-cbef-4e01-ba5f-804a984024ee | I24: regular | J24: 2026-09-13T18:00:00+00:00 | K24: e6c4ce63-cbef-4e01-ba5f-804a984024ee | L24: Cincinnati Bengals | M24: =FALSE() -> FALSE | O24: NFL | P24: East | Q24: db3ed416-54bc-44d6-86dc-49b6cc79a2ef | R24: Cleveland Browns | S24: home | T24: L | U24: 15 | V24: 27 | W24: -12 | X24: 1 | Y24: 1 | Z24: -1 | AA24: 2 | AB24: 73.44 | AC24: 66.15 | AD24: 0.6777
A25: 0.1 | B25: simulator | C25: run-42 | D25: 42 | E25: S0001 | F25: 2 | G25: S0001-w02-g06 | H25: S0001-w02-g06:db3ed416-54bc-44d6-86dc-49b6cc79a2ef | I25: regular | J25: 2026-09-13T18:00:00+00:00 | K25: db3ed416-54bc-44d6-86dc-49b6cc79a2ef | L25: Cleveland Browns | M25: =FALSE() -> FALSE | O25: NFL | P25: East | Q25: e6c4ce63-cbef-4e01-ba5f-804a984024ee | R25: Cincinnati Bengals | S25: away | T25: W | U25: 27 | V25: 15 | W25: 12 | X25: 1 | Y25: 1 | Z25: 1 | AA25: 2 | AB25: 66.15 | AC25: 73.44 | AD25: 0.3223
A26: 0.1 | B26: simulator | C26: run-42 | D26: 42 | E26: S0001 | F26: 3 | G26: S0001-w03-g01 | H26: S0001-w03-g01:22dda48d-9e4d-469d-8e17-eb48dd5a58d7 | I26: regular | J26: 2026-09-20T18:00:00+00:00 | K26: 22dda48d-9e4d-469d-8e17-eb48dd5a58d7 | L26: Buffalo Bills | M26: =FALSE() -> FALSE | O26: NFL | P26: East | Q26: 7e907f08-6389-4d4f-b2b1-a4899a80a576 | R26: Chicago Bears | S26: home | T26: L | U26: 11 | V26: 14 | W26: -3 | X26: 2 | Y26: 1 | Z26: -1 | AA26: 4 | AB26: 83.18 | AC26: 65.53 | AD26: 0.8281
A27: 0.1 | B27: simulator | C27: run-42 | D27: 42 | E27: S0001 | F27: 3 | G27: S0001-w03-g01 | H27: S0001-w03-g01:7e907f08-6389-4d4f-b2b1-a4899a80a576 | I27: regular | J27: 2026-09-20T18:00:00+00:00 | K27: 7e907f08-6389-4d4f-b2b1-a4899a80a576 | L27: Chicago Bears | M27: =FALSE() -> FALSE | O27: NFL | P27: West | Q27: 22dda48d-9e4d-469d-8e17-eb48dd5a58d7 | R27: Buffalo Bills | S27: away | T27: W | U27: 14 | V27: 11 | W27: 3 | X27: 3 | Y27: 0 | Z27: 3 | AA27: 6 | AB27: 65.53 | AC27: 83.18 | AD27: 0.1719
A28: 0.1 | B28: simulator | C28: run-42 | D28: 42 | E28: S0001 | F28: 3 | G28: S0001-w03-g02 | H28: S0001-w03-g02:64336ace-1ead-4eed-a112-3d402edc6d84 | I28: regular | J28: 2026-09-20T18:00:00+00:00 | K28: 64336ace-1ead-4eed-a112-3d402edc6d84 | L28: New Orleans Saints | M28: =FALSE() -> FALSE | O28: NFL | P28: West | Q28: d6d0b322-6a53-4df9-9ae1-5abb357a05ef | R28: Carolina Panthers | S28: home | T28: W | U28: 22 | V28: 19 | W28: 3 | X28: 2 | Y28: 1 | Z28: 1 | AA28: 4 | AB28: 68.39 | AC28: 58.14 | AD28: 0.7271
A29: 0.1 | B29: simulator | C29: run-42 | D29: 42 | E29: S0001 | F29: 3 | G29: S0001-w03-g02 | H29: S0001-w03-g02:d6d0b322-6a53-4df9-9ae1-5abb357a05ef | I29: regular | J29: 2026-09-20T18:00:00+00:00 | K29: d6d0b322-6a53-4df9-9ae1-5abb357a05ef | L29: Carolina Panthers | M29: =FALSE() -> FALSE | O29: NFL | P29: West | Q29: 64336ace-1ead-4eed-a112-3d402edc6d84 | R29: New Orleans Saints | S29: away | T29: L | U29: 19 | V29: 22 | W29: -3 | X29: 1 | Y29: 2 | Z29: -2 | AA29: 2 | AB29: 58.14 | AC29: 68.39 | AD29: 0.2729
A30: 0.1 | B30: simulator | C30: run-42 | D30: 42 | E30: S0001 | F30: 3 | G30: S0001-w03-g03 | H30: S0001-w03-g03:00000000-0000-0000-0000-000000000001 | I30: regular | J30: 2026-09-20T18:00:00+00:00 | K30: 00000000-0000-0000-0000-000000000001 | L30: Player Team | M30: =TRUE() -> TRUE | N30: player_001 | O30: NFL | P30: West | Q30: a866ce30-5869-4188-b93b-d415e1f97a9e | R30: Denver Broncos | S30: home | T30: W | U30: 25 | V30: 19 | W30: 6 | X30: 1 | Y30: 2 | Z30: 1 | AA30: 2 | AB30: 70.69 | AC30: 71.54 | AD30: 0.5231
A31: 0.1 | B31: simulator | C31: run-42 | D31: 42 | E31: S0001 | F31: 3 | G31: S0001-w03-g03 | H31: S0001-w03-g03:a866ce30-5869-4188-b93b-d415e1f97a9e | I31: regular | J31: 2026-09-20T18:00:00+00:00 | K31: a866ce30-5869-4188-b93b-d415e1f97a9e | L31: Denver Broncos | M31: =FALSE() -> FALSE | O31: NFL | P31: West | Q31: 00000000-0000-0000-0000-000000000001 | R31: Player Team | S31: away | T31: L | U31: 19 | V31: 25 | W31: -6 | X31: 0 | Y31: 3 | Z31: -3 | AA31: 0 | AB31: 71.54 | AC31: 70.69 | AD31: 0.4769
A32: 0.1 | B32: simulator | C32: run-42 | D32: 42 | E32: S0001 | F32: 3 | G32: S0001-w03-g04 | H32: S0001-w03-g04:466adf39-b0a1-4b20-ba94-f22a82ff92a2 | I32: regular | J32: 2026-09-20T18:00:00+00:00 | K32: 466adf39-b0a1-4b20-ba94-f22a82ff92a2 | L32: Los Angeles Rams | M32: =FALSE() -> FALSE | O32: NFL | P32: West | Q32: 4379eea3-230b-4c63-8c33-06dacd51a349 | R32: New England Patriots | S32: home | T32: W | U32: 33 | V32: 24 | W32: 9 | X32: 2 | Y32: 1 | Z32: 1 | AA32: 4 | AB32: 76.32 | AC32: 69.16 | AD32: 0.6755
A33: 0.1 | B33: simulator | C33: run-42 | D33: 42 | E33: S0001 | F33: 3 | G33: S0001-w03-g04 | H33: S0001-w03-g04:4379eea3-230b-4c63-8c33-06dacd51a349 | I33: regular | J33: 2026-09-20T18:00:00+00:00 | K33: 4379eea3-230b-4c63-8c33-06dacd51a349 | L33: New England Patriots | M33: =FALSE() -> FALSE | O33: NFL | P33: East | Q33: 466adf39-b0a1-4b20-ba94-f22a82ff92a2 | R33: Los Angeles Rams | S33: away | T33: L | U33: 24 | V33: 33 | W33: -9 | X33: 1 | Y33: 2 | Z33: -1 | AA33: 2 | AB33: 69.16 | AC33: 76.32 | AD33: 0.3245
A34: 0.1 | B34: simulator | C34: run-42 | D34: 42 | E34: S0001 | F34: 3 | G34: S0001-w03-g05 | H34: S0001-w03-g05:88e80e3c-3511-403f-9033-332c76820e54 | I34: regular | J34: 2026-09-20T18:00:00+00:00 | K34: 88e80e3c-3511-403f-9033-332c76820e54 | L34: New York Giants | M34: =FALSE() -> FALSE | O34: NFL | P34: East | Q34: db3ed416-54bc-44d6-86dc-49b6cc79a2ef | R34: Cleveland Browns | S34: home | T34: L | U34: 16 | V34: 26 | W34: -10 | X34: 1 | Y34: 2 | Z34: -1 | AA34: 2 | AB34: 63.04 | AC34: 66.15 | AD34: 0.4777
A35: 0.1 | B35: simulator | C35: run-42 | D35: 42 | E35: S0001 | F35: 3 | G35: S0001-w03-g05 | H35: S0001-w03-g05:db3ed416-54bc-44d6-86dc-49b6cc79a2ef | I35: regular | J35: 2026-09-20T18:00:00+00:00 | K35: db3ed416-54bc-44d6-86dc-49b6cc79a2ef | L35: Cleveland Browns | M35: =FALSE() -> FALSE | O35: NFL | P35: East | Q35: 88e80e3c-3511-403f-9033-332c76820e54 | R35: New York Giants | S35: away | T35: W | U35: 26 | V35: 16 | W35: 10 | X35: 2 | Y35: 1 | Z35: 2 | AA35: 4 | AB35: 66.15 | AC35: 63.04 | AD35: 0.5223
A36: 0.1 | B36: simulator | C36: run-42 | D36: 42 | E36: S0001 | F36: 3 | G36: S0001-w03-g06 | H36: S0001-w03-g06:e6c4ce63-cbef-4e01-ba5f-804a984024ee | I36: regular | J36: 2026-09-20T18:00:00+00:00 | K36: e6c4ce63-cbef-4e01-ba5f-804a984024ee | L36: Cincinnati Bengals | M36: =FALSE() -> FALSE | O36: NFL | P36: East | Q36: 3d743b76-bc76-4249-b550-d5a09b0e071a | R36: Dallas Cowboys | S36: home | T36: W | U36: 40 | V36: 18 | W36: 22 | X36: 2 | Y36: 1 | Z36: 1 | AA36: 4 | AB36: 73.44 | AC36: 76.13 | AD36: 0.4861
A37: 0.1 | B37: simulator | C37: run-42 | D37: 42 | E37: S0001 | F37: 3 | G37: S0001-w03-g06 | H37: S0001-w03-g06:3d743b76-bc76-4249-b550-d5a09b0e071a | I37: regular | J37: 2026-09-20T18:00:00+00:00 | K37: 3d743b76-bc76-4249-b550-d5a09b0e071a | L37: Dallas Cowboys | M37: =FALSE() -> FALSE | O37: NFL | P37: East | Q37: e6c4ce63-cbef-4e01-ba5f-804a984024ee | R37: Cincinnati Bengals | S37: away | T37: L | U37: 18 | V37: 40 | W37: -22 | X37: 1 | Y37: 2 | Z37: -1 | AA37: 2 | AB37: 76.13 | AC37: 73.44 | AD37: 0.5139
A38: 0.1 | B38: simulator | C38: run-42 | D38: 42 | E38: S0001 | F38: 4 | G38: S0001-w04-g01 | H38: S0001-w04-g01:64336ace-1ead-4eed-a112-3d402edc6d84 | I38: regular | J38: 2026-09-27T18:00:00+00:00 | K38: 64336ace-1ead-4eed-a112-3d402edc6d84 | L38: New Orleans Saints | M38: =FALSE() -> FALSE | O38: NFL | P38: West | Q38: 22dda48d-9e4d-469d-8e17-eb48dd5a58d7 | R38: Buffalo Bills | S38: home | T38: L | U38: 17 | V38: 21 | W38: -4 | X38: 2 | Y38: 2 | Z38: -1 | AA38: 4 | AB38: 68.39 | AC38: 83.18 | AD38: 0.2644
A39: 0.1 | B39: simulator | C39: run-42 | D39: 42 | E39: S0001 | F39: 4 | G39: S0001-w04-g01 | H39: S0001-w04-g01:22dda48d-9e4d-469d-8e17-eb48dd5a58d7 | I39: regular | J39: 2026-09-27T18:00:00+00:00 | K39: 22dda48d-9e4d-469d-8e17-eb48dd5a58d7 | L39: Buffalo Bills | M39: =FALSE() -> FALSE | O39: NFL | P39: East | Q39: 64336ace-1ead-4eed-a112-3d402edc6d84 | R39: New Orleans Saints | S39: away | T39: W | U39: 21 | V39: 17 | W39: 4 | X39: 3 | Y39: 1 | Z39: 1 | AA39: 6 | AB39: 83.18 | AC39: 68.39 | AD39: 0.7356
A40: 0.1 | B40: simulator | C40: run-42 | D40: 42 | E40: S0001 | F40: 4 | G40: S0001-w04-g02 | H40: S0001-w04-g02:7e907f08-6389-4d4f-b2b1-a4899a80a576 | I40: regular | J40: 2026-09-27T18:00:00+00:00 | K40: 7e907f08-6389-4d4f-b2b1-a4899a80a576 | L40: Chicago Bears | M40: =FALSE() -> FALSE | O40: NFL | P40: West | Q40: a866ce30-5869-4188-b93b-d415e1f97a9e | R40: Denver Broncos | S40: home | T40: L | U40: 23 | V40: 34 | W40: -11 | X40: 3 | Y40: 1 | Z40: -1 | AA40: 6 | AB40: 65.53 | AC40: 71.54 | AD40: 0.4205
...

Sheet Sample_Standings
A1: Sample_Standings | season S0001, seed 42
A2: All columns except sim_placement are formulas over Sample_Games.
A4: team_id | B4: team_name | C4: division | D4: is_player_team | E4: games_played | F4: wins | G4: losses | H4: standing_points | I4: points_for | J4: points_against | K4: point_diff | L4: sort_key | M4: placement (formula) | N4: sim_placement (gos_sim.py) | O4: match
A5: 22dda48d-9e4d-469d-8e17-eb48dd5a58d7 | B5: Buffalo Bills | C5: East | D5: =FALSE() -> FALSE | E5: =COUNTIFS(Sample_Games!$K$2:$K$121,A5) -> 10 | F5: =COUNTIFS(Sample_Games!$K$2:$K$121,A5,Sample_Games!$T$2:$T$121,"W") -> 6 | G5: =COUNTIFS(Sample_Games!$K$2:$K$121,A5,Sample_Games!$T$2:$T$121,"L") -> 4 | H5: =F5*points_per_win -> 12 | I5: =SUMIFS(Sample_Games!$U$2:$U$121,Sample_Games!$K$2:$K$121,A5) -> 268 | J5: =SUMIFS(Sample_Games!$V$2:$V$121,Sample_Games!$K$2:$K$121,A5) -> 256 | K5: =I5-J5 -> 12 | L5: =H5*100000000+(K5+10000)*1000+I5 -> 1210012268 | M5: =COUNTIF($L$5:$L$16,">"&L5)+1 -> 5 | N5: 5 | O5: =IF(M5=N5,"OK","DIFF") -> OK
A6: 4379eea3-230b-4c63-8c33-06dacd51a349 | B6: New England Patriots | C6: East | D6: =FALSE() -> FALSE | E6: =COUNTIFS(Sample_Games!$K$2:$K$121,A6) -> 10 | F6: =COUNTIFS(Sample_Games!$K$2:$K$121,A6,Sample_Games!$T$2:$T$121,"W") -> 5 | G6: =COUNTIFS(Sample_Games!$K$2:$K$121,A6,Sample_Games!$T$2:$T$121,"L") -> 5 | H6: =F6*points_per_win -> 10 | I6: =SUMIFS(Sample_Games!$U$2:$U$121,Sample_Games!$K$2:$K$121,A6) -> 235 | J6: =SUMIFS(Sample_Games!$V$2:$V$121,Sample_Games!$K$2:$K$121,A6) -> 256 | K6: =I6-J6 -> -21 | L6: =H6*100000000+(K6+10000)*1000+I6 -> 1009979235 | M6: =COUNTIF($L$5:$L$16,">"&L6)+1 -> 7 | N6: 7 | O6: =IF(M6=N6,"OK","DIFF") -> OK
A7: 88e80e3c-3511-403f-9033-332c76820e54 | B7: New York Giants | C7: East | D7: =FALSE() -> FALSE | E7: =COUNTIFS(Sample_Games!$K$2:$K$121,A7) -> 10 | F7: =COUNTIFS(Sample_Games!$K$2:$K$121,A7,Sample_Games!$T$2:$T$121,"W") -> 2 | G7: =COUNTIFS(Sample_Games!$K$2:$K$121,A7,Sample_Games!$T$2:$T$121,"L") -> 8 | H7: =F7*points_per_win -> 4 | I7: =SUMIFS(Sample_Games!$U$2:$U$121,Sample_Games!$K$2:$K$121,A7) -> 246 | J7: =SUMIFS(Sample_Games!$V$2:$V$121,Sample_Games!$K$2:$K$121,A7) -> 263 | K7: =I7-J7 -> -17 | L7: =H7*100000000+(K7+10000)*1000+I7 -> 409983246 | M7: =COUNTIF($L$5:$L$16,">"&L7)+1 -> 12 | N7: 12 | O7: =IF(M7=N7,"OK","DIFF") -> OK
A8: 3d743b76-bc76-4249-b550-d5a09b0e071a | B8: Dallas Cowboys | C8: East | D8: =FALSE() -> FALSE | E8: =COUNTIFS(Sample_Games!$K$2:$K$121,A8) -> 10 | F8: =COUNTIFS(Sample_Games!$K$2:$K$121,A8,Sample_Games!$T$2:$T$121,"W") -> 5 | G8: =COUNTIFS(Sample_Games!$K$2:$K$121,A8,Sample_Games!$T$2:$T$121,"L") -> 5 | H8: =F8*points_per_win -> 10 | I8: =SUMIFS(Sample_Games!$U$2:$U$121,Sample_Games!$K$2:$K$121,A8) -> 260 | J8: =SUMIFS(Sample_Games!$V$2:$V$121,Sample_Games!$K$2:$K$121,A8) -> 327 | K8: =I8-J8 -> -67 | L8: =H8*100000000+(K8+10000)*1000+I8 -> 1009933260 | M8: =COUNTIF($L$5:$L$16,">"&L8)+1 -> 8 | N8: 8 | O8: =IF(M8=N8,"OK","DIFF") -> OK
A9: e6c4ce63-cbef-4e01-ba5f-804a984024ee | B9: Cincinnati Bengals | C9: East | D9: =FALSE() -> FALSE | E9: =COUNTIFS(Sample_Games!$K$2:$K$121,A9) -> 10 | F9: =COUNTIFS(Sample_Games!$K$2:$K$121,A9,Sample_Games!$T$2:$T$121,"W") -> 7 | G9: =COUNTIFS(Sample_Games!$K$2:$K$121,A9,Sample_Games!$T$2:$T$121,"L") -> 3 | H9: =F9*points_per_win -> 14 | I9: =SUMIFS(Sample_Games!$U$2:$U$121,Sample_Games!$K$2:$K$121,A9) -> 253 | J9: =SUMIFS(Sample_Games!$V$2:$V$121,Sample_Games!$K$2:$K$121,A9) -> 223 | K9: =I9-J9 -> 30 | L9: =H9*100000000+(K9+10000)*1000+I9 -> 1410030253 | M9: =COUNTIF($L$5:$L$16,">"&L9)+1 -> 2 | N9: 2 | O9: =IF(M9=N9,"OK","DIFF") -> OK
A10: db3ed416-54bc-44d6-86dc-49b6cc79a2ef | B10: Cleveland Browns | C10: East | D10: =FALSE() -> FALSE | E10: =COUNTIFS(Sample_Games!$K$2:$K$121,A10) -> 10 | F10: =COUNTIFS(Sample_Games!$K$2:$K$121,A10,Sample_Games!$T$2:$T$121,"W") -> 4 | G10: =COUNTIFS(Sample_Games!$K$2:$K$121,A10,Sample_Games!$T$2:$T$121,"L") -> 6 | H10: =F10*points_per_win -> 8 | I10: =SUMIFS(Sample_Games!$U$2:$U$121,Sample_Games!$K$2:$K$121,A10) -> 236 | J10: =SUMIFS(Sample_Games!$V$2:$V$121,Sample_Games!$K$2:$K$121,A10) -> 250 | K10: =I10-J10 -> -14 | L10: =H10*100000000+(K10+10000)*1000+I10 -> 809986236 | M10: =COUNTIF($L$5:$L$16,">"&L10)+1 -> 10 | N10: 10 | O10: =IF(M10=N10,"OK","DIFF") -> OK
A11: 466adf39-b0a1-4b20-ba94-f22a82ff92a2 | B11: Los Angeles Rams | C11: West | D11: =FALSE() -> FALSE | E11: =COUNTIFS(Sample_Games!$K$2:$K$121,A11) -> 10 | F11: =COUNTIFS(Sample_Games!$K$2:$K$121,A11,Sample_Games!$T$2:$T$121,"W") -> 7 | G11: =COUNTIFS(Sample_Games!$K$2:$K$121,A11,Sample_Games!$T$2:$T$121,"L") -> 3 | H11: =F11*points_per_win -> 14 | I11: =SUMIFS(Sample_Games!$U$2:$U$121,Sample_Games!$K$2:$K$121,A11) -> 253 | J11: =SUMIFS(Sample_Games!$V$2:$V$121,Sample_Games!$K$2:$K$121,A11) -> 212 | K11: =I11-J11 -> 41 | L11: =H11*100000000+(K11+10000)*1000+I11 -> 1410041253 | M11: =COUNTIF($L$5:$L$16,">"&L11)+1 -> 1 | N11: 1 | O11: =IF(M11=N11,"OK","DIFF") -> OK
A12: a866ce30-5869-4188-b93b-d415e1f97a9e | B12: Denver Broncos | C12: West | D12: =FALSE() -> FALSE | E12: =COUNTIFS(Sample_Games!$K$2:$K$121,A12) -> 10 | F12: =COUNTIFS(Sample_Games!$K$2:$K$121,A12,Sample_Games!$T$2:$T$121,"W") -> 6 | G12: =COUNTIFS(Sample_Games!$K$2:$K$121,A12,Sample_Games!$T$2:$T$121,"L") -> 4 | H12: =F12*points_per_win -> 12 | I12: =SUMIFS(Sample_Games!$U$2:$U$121,Sample_Games!$K$2:$K$121,A12) -> 269 | J12: =SUMIFS(Sample_Games!$V$2:$V$121,Sample_Games!$K$2:$K$121,A12) -> 239 | K12: =I12-J12 -> 30 | L12: =H12*100000000+(K12+10000)*1000+I12 -> 1210030269 | M12: =COUNTIF($L$5:$L$16,">"&L12)+1 -> 4 | N12: 4 | O12: =IF(M12=N12,"OK","DIFF") -> OK
A13: 64336ace-1ead-4eed-a112-3d402edc6d84 | B13: New Orleans Saints | C13: West | D13: =FALSE() -> FALSE | E13: =COUNTIFS(Sample_Games!$K$2:$K$121,A13) -> 10 | F13: =COUNTIFS(Sample_Games!$K$2:$K$121,A13,Sample_Games!$T$2:$T$121,"W") -> 5 | G13: =COUNTIFS(Sample_Games!$K$2:$K$121,A13,Sample_Games!$T$2:$T$121,"L") -> 5 | H13: =F13*points_per_win -> 10 | I13: =SUMIFS(Sample_Games!$U$2:$U$121,Sample_Games!$K$2:$K$121,A13) -> 219 | J13: =SUMIFS(Sample_Games!$V$2:$V$121,Sample_Games!$K$2:$K$121,A13) -> 218 | K13: =I13-J13 -> 1 | L13: =H13*100000000+(K13+10000)*1000+I13 -> 1010001219 | M13: =COUNTIF($L$5:$L$16,">"&L13)+1 -> 6 | N13: 6 | O13: =IF(M13=N13,"OK","DIFF") -> OK
A14: 7e907f08-6389-4d4f-b2b1-a4899a80a576 | B14: Chicago Bears | C14: West | D14: =FALSE() -> FALSE | E14: =COUNTIFS(Sample_Games!$K$2:$K$121,A14) -> 10 | F14: =COUNTIFS(Sample_Games!$K$2:$K$121,A14,Sample_Games!$T$2:$T$121,"W") -> 6 | G14: =COUNTIFS(Sample_Games!$K$2:$K$121,A14,Sample_Games!$T$2:$T$121,"L") -> 4 | H14: =F14*points_per_win -> 12 | I14: =SUMIFS(Sample_Games!$U$2:$U$121,Sample_Games!$K$2:$K$121,A14) -> 267 | J14: =SUMIFS(Sample_Games!$V$2:$V$121,Sample_Games!$K$2:$K$121,A14) -> 233 | K14: =I14-J14 -> 34 | L14: =H14*100000000+(K14+10000)*1000+I14 -> 1210034267 | M14: =COUNTIF($L$5:$L$16,">"&L14)+1 -> 3 | N14: 3 | O14: =IF(M14=N14,"OK","DIFF") -> OK
A15: d6d0b322-6a53-4df9-9ae1-5abb357a05ef | B15: Carolina Panthers | C15: West | D15: =FALSE() -> FALSE | E15: =COUNTIFS(Sample_Games!$K$2:$K$121,A15) -> 10 | F15: =COUNTIFS(Sample_Games!$K$2:$K$121,A15,Sample_Games!$T$2:$T$121,"W") -> 3 | G15: =COUNTIFS(Sample_Games!$K$2:$K$121,A15,Sample_Games!$T$2:$T$121,"L") -> 7 | H15: =F15*points_per_win -> 6 | I15: =SUMIFS(Sample_Games!$U$2:$U$121,Sample_Games!$K$2:$K$121,A15) -> 188 | J15: =SUMIFS(Sample_Games!$V$2:$V$121,Sample_Games!$K$2:$K$121,A15) -> 230 | K15: =I15-J15 -> -42 | L15: =H15*100000000+(K15+10000)*1000+I15 -> 609958188 | M15: =COUNTIF($L$5:$L$16,">"&L15)+1 -> 11 | N15: 11 | O15: =IF(M15=N15,"OK","DIFF") -> OK
A16: 00000000-0000-0000-0000-000000000001 | B16: Player Team | C16: West | D16: =TRUE() -> TRUE | E16: =COUNTIFS(Sample_Games!$K$2:$K$121,A16) -> 10 | F16: =COUNTIFS(Sample_Games!$K$2:$K$121,A16,Sample_Games!$T$2:$T$121,"W") -> 4 | G16: =COUNTIFS(Sample_Games!$K$2:$K$121,A16,Sample_Games!$T$2:$T$121,"L") -> 6 | H16: =F16*points_per_win -> 8 | I16: =SUMIFS(Sample_Games!$U$2:$U$121,Sample_Games!$K$2:$K$121,A16) -> 301 | J16: =SUMIFS(Sample_Games!$V$2:$V$121,Sample_Games!$K$2:$K$121,A16) -> 288 | K16: =I16-J16 -> 13 | L16: =H16*100000000+(K16+10000)*1000+I16 -> 810013301 | M16: =COUNTIF($L$5:$L$16,">"&L16)+1 -> 9 | N16: 9 | O16: =IF(M16=N16,"OK","DIFF") -> OK

Sheet Validation
A1: Validation | every batch must pass, simulator or live
A2: Live formulas over Sample_Games / Sample_Standings. Implement the same checks in code (gos_sim.validate).
A4: # | B4: Check | C4: Why | D4: Formula result | E4: Status
A5: 1 | B5: League wins = league losses | C5: Every game has one winner and one loser. Today's in-game coin flip fails this | D5: =COUNTIF(Sample_Games!$T$2:$T$121,"W")=COUNTIF(Sample_Games!$T$2:$T$121,"L") -> TRUE | E5: =IF(D5,"PASS","FAIL") -> PASS
A6: 2 | B6: Every game_id has exactly 2 rows | C6: One row per team per game | D6: =SUMPRODUCT((COUNTIF(Sample_Games!$G$2:$G$121,Sample_Games!$G$2:$G$121)<>2)*1)=0 -> TRUE | E6: =IF(D6,"PASS","FAIL") -> PASS
A7: 3 | B7: event_id is unique | C7: Rewards are idempotent on event_id | D7: =SUMPRODUCT((COUNTIF(Sample_Games!$H$2:$H$121,Sample_Games!$H$2:$H$121)>1)*1)=0 -> TRUE | E7: =IF(D7,"PASS","FAIL") -> PASS
A8: 4 | B8: Score agrees with result | C8: W exactly when points_for > points_against | D8: =SUMPRODUCT(((Sample_Games!$T$2:$T$121="W")<>(Sample_Games!$U$2:$U$121>Sample_Games!$V$2:$V$121))*1)=0 -> TRUE | E8: =IF(D8,"PASS","FAIL") -> PASS
A9: 5 | B9: margin = points_for - points_against | C9: Derived field is consistent | D9: =SUMPRODUCT((Sample_Games!$W$2:$W$121<>Sample_Games!$U$2:$U$121-Sample_Games!$V$2:$V$121)*1)=0 -> TRUE | E9: =IF(D9,"PASS","FAIL") -> PASS
A10: 6 | B10: Each team plays weeks_per_season games | C10: No team skipped or doubled | D10: =SUMPRODUCT((Sample_Standings!$E$5:$E$16<>weeks_per_season)*1)=0 -> TRUE | E10: =IF(D10,"PASS","FAIL") -> PASS
A11: 7 | B11: Exactly one player-team row per week | C11: Rewards target one user | D11: =COUNTIF(Sample_Games!$M$2:$M$121,TRUE())=weeks_per_season -> TRUE | E11: =IF(D11,"PASS","FAIL") -> PASS
A12: 8 | B12: Placements are unique 1..N | C12: Season rewards need a clean rank | D12: =AND(SUMPRODUCT((COUNTIF(Sample_Standings!$M$5:$M$16,Sample_Standings!$M$5:$M$16)<>1)*1)=0,MAX(Sample_Standings!$M$5:$M$16)=teams_per_season) -> TRUE | E12: =IF(D12,"PASS","FAIL") -> PASS
A13: 9 | B13: Formula placement = simulator placement | C13: Excel and gos_sim.py agree on standings + tiebreaks | D13: =COUNTIF(Sample_Standings!$O$5:$O$16,"DIFF")=0 -> TRUE | E13: =IF(D13,"PASS","FAIL") -> PASS
A14: 10 | B14: win_probability in 0..1 | C14: Sanity | D14: =AND(MIN(Sample_Games!$AD$2:$AD$121)>=0,MAX(Sample_Games!$AD$2:$AD$121)<=1) -> TRUE | E14: =IF(D14,"PASS","FAIL") -> PASS
A15: 11 | B15: Strength weights sum to 1 | C15: Config sanity | D15: =ABS(w_offence+w_defence+w_special_teams-1)<0.0001 -> TRUE | E15: =IF(D15,"PASS","FAIL") -> PASS
B17: All checks | E17: =IF(COUNTIF(E5:E15,"PASS")=11,"ALL PASS","FAIL") -> ALL PASS

Sheet Monte_Carlo
A1: Monte_Carlo | 2,000 seasons, seed 7, default config
A2: Simulator output (gos_sim.py). These are the replication targets for anyone rebuilding the engine.
A4: team_name | B4: is_player_team | C4: team_strength | D4: avg_wins | E4: P(1st) | F4: P(top 3) | G4: avg_placement | H4: avg_point_diff | I4: avg_longest_streak
A5: Buffalo Bills | B5: =FALSE() -> FALSE | C5: 83.18 | D5: 7.459 | E5: 0.4655 | F5: 0.789 | G5: 2.42 | H5: 43.1 | I5: 4.87
A6: Los Angeles Rams | B6: =FALSE() -> FALSE | C6: 76.32 | D6: 6.372 | E6: 0.171 | F6: 0.52 | G6: 4.02 | H6: 22.1 | I6: 3.74
A7: Dallas Cowboys | B7: =FALSE() -> FALSE | C7: 76.13 | D7: 5.75 | E7: 0.0945 | F7: 0.347 | G7: 5.16 | H7: 11.7 | I7: 3.39
A8: Cincinnati Bengals | B8: =FALSE() -> FALSE | C8: 73.44 | D8: 5.843 | E8: 0.1 | F8: 0.37 | G8: 4.96 | H8: 13.1 | I8: 3.48
A9: Denver Broncos | B9: =FALSE() -> FALSE | C9: 71.54 | D9: 5.393 | E9: 0.0495 | F9: 0.2585 | G9: 5.76 | H9: 6 | I9: 2.97
A10: Player Team | B10: =TRUE() -> TRUE | C10: 70.69 | D10: 5.248 | E10: 0.0515 | F10: 0.2335 | G10: 6.05 | H10: 3.6 | I10: 3.14
A11: New England Patriots | B11: =FALSE() -> FALSE | C11: 69.16 | D11: 4.651 | E11: 0.02 | F11: 0.1345 | G11: 7.16 | H11: -4.9 | I11: 2.52
A12: New Orleans Saints | B12: =FALSE() -> FALSE | C12: 68.39 | D12: 4.466 | E12: 0.0145 | F12: 0.1155 | G12: 7.47 | H12: -8.3 | I12: 2.45
A13: Cleveland Browns | B13: =FALSE() -> FALSE | C13: 66.15 | D13: 4.057 | E13: 0.0115 | F13: 0.0745 | G13: 8.19 | H13: -15.3 | I13: 2.17
A14: Chicago Bears | B14: =FALSE() -> FALSE | C14: 65.53 | D14: 4.29 | E14: 0.0115 | F14: 0.0825 | G14: 7.82 | H14: -11.3 | I14: 2.38
A15: New York Giants | B15: =FALSE() -> FALSE | C15: 63.04 | D15: 3.954 | E15: 0.0095 | F15: 0.066 | G15: 8.42 | H15: -18.4 | I15: 2.25
A16: Carolina Panthers | B16: =FALSE() -> FALSE | C16: 58.14 | D16: 2.518 | E16: 0.001 | F16: 0.009 | G16: 10.56 | H16: -41.4 | I16: 1.42
A18: Player Team final placement distribution
A19: placement | B19: seasons | C19: share
A20: 1 | B20: 103 | C20: =B20/SUM($B$20:$B$31) -> 0.0515
A21: 2 | B21: 167 | C21: =B21/SUM($B$20:$B$31) -> 0.0835
A22: 3 | B22: 197 | C22: =B22/SUM($B$20:$B$31) -> 0.0985
A23: 4 | B23: 211 | C23: =B23/SUM($B$20:$B$31) -> 0.1055
A24: 5 | B24: 244 | C24: =B24/SUM($B$20:$B$31) -> 0.122
A25: 6 | B25: 210 | C25: =B25/SUM($B$20:$B$31) -> 0.105
A26: 7 | B26: 195 | C26: =B26/SUM($B$20:$B$31) -> 0.0975
A27: 8 | B27: 203 | C27: =B27/SUM($B$20:$B$31) -> 0.1015
A28: 9 | B28: 154 | C28: =B28/SUM($B$20:$B$31) -> 0.077
A29: 10 | B29: 148 | C29: =B29/SUM($B$20:$B$31) -> 0.074
A30: 11 | B30: 116 | C30: =B30/SUM($B$20:$B$31) -> 0.058
A31: 12 | B31: 52 | C31: =B31/SUM($B$20:$B$31) -> 0.026
